<?xml version="1.0" ?>
<!-- =================================================================================== -->
<!-- |    This document was autogenerated by xacro from hummingbird.xacro              | -->
<!-- |    EDITING THIS FILE BY HAND IS NOT RECOMMENDED                                 | -->
<!-- =================================================================================== -->
<!--
  Copyright 2015 Fadri Furrer, ASL, ETH Zurich, Switzerland
  Copyright 2015 Michael Burri, ASL, ETH Zurich, Switzerland
  Copyright 2015 Mina Kamel, ASL, ETH Zurich, Switzerland
  Copyright 2015 Janosch Nikolic, ASL, ETH Zurich, Switzerland
  Copyright 2015 Markus Achtelik, ASL, ETH Zurich, Switzerland

  Licensed under the Apache License, Version 2.0 (the "License");
  you may not use this file except in compliance with the License.
  You may obtain a copy of the License at

  http://www.apache.org/licenses/LICENSE-2.0

  Unless required by applicable law or agreed to in writing, software
  distributed under the License is distributed on an "AS IS" BASIS,
  WITHOUT WARRANTIES OR CONDITIONS OF ANY KIND, either express or implied.
  See the License for the specific language governing permissions and
  limitations under the License.
-->
<robot name="hummingbird">
  <!-- Wind field -->
  <!--  <xacro:wind_plugin_macro
    namespace="${namespace}"
    xyz_offset="0 0 0"
    wind_direction="1 0 0"
    wind_force_mean="0.0"
    wind_gust_direction="0 1 0"
    wind_gust_duration="0.0"
    wind_gust_start="0.0"
    wind_gust_force_mean="0.0"
    wind_speed_mean="5.0"
    use_custom_static_wind_field="true"
    custom_wind_field_path="$(find rotors_gazebo)/models/hemicyl/wind_field_hemicyl.txt">
  </xacro:wind_plugin_macro> -->
  <link name="h1/base_link"/>
  <joint name="h1/base_joint" type="fixed">
    <origin rpy="0 0 0" xyz="0 0 0"/>
    <parent link="h1/base_link"/>
    <child link="h1/base_link_inertia"/>
  </joint>
  <link name="h1/base_link_inertia">
    <inertial>
      <mass value="0.28"/>
      <!-- [kg] -->
      <origin xyz="0 0 0"/>
      <inertia ixx="0.007" ixy="0.0" ixz="0.0" iyy="0.007" iyz="0.0" izz="0.012"/>
    </inertial>
    <visual>
      <origin rpy="0 0 0" xyz="0 0 0"/>
      <geometry>
        <mesh filename="package://rotors_description/meshes/hummingbird.dae" scale="1 1 1"/>
      </geometry>
      <material name="blue">
        <color rgba="0 0 0.8 1"/>
      </material>
    </visual>
    <collision>
      <origin rpy="0 0 0" xyz="0 0 0"/>
      <geometry>
        <box size="0.1 0.1 0.12"/>
        <!-- [m] [m] [m] -->
      </geometry>
    </collision>
  </link>
  <!-- attach multirotor_base_plugin to the base_link -->
  <gazebo>
    <plugin filename="librotors_gazebo_multirotor_base_plugin.so" name="multirotor_base_plugin">
      <robotNamespace>h1</robotNamespace>
      <linkName>h1/base_link</linkName>
      <rotorVelocitySlowdownSim>10</rotorVelocitySlowdownSim>
    </plugin>
  </gazebo>
  <joint name="h1/rotor_0_joint" type="continuous">
    <origin rpy="0 0 0" xyz="0.17 0 0.01"/>
    <axis xyz="0 0 1"/>
    <!-- TODO(ff): not currently set because it's not yet supported -->
    <!-- <limit effort="2000" velocity="${max_rot_velocity}" /> -->
    <parent link="h1/base_link"/>
    <child link="h1/rotor_0"/>
  </joint>
  <link name="h1/rotor_0">
    <inertial>
      <mass value="0.009"/>
      <!-- [kg] -->
      <inertia ixx="1.754999298e-06" ixy="0.0" ixz="0.0" iyy="7.506746997300002e-05" iyz="0.0" izz="7.668746932500001e-05"/>
    </inertial>
    <visual>
      <geometry>
        <mesh filename="package://rotors_description/meshes/propeller_cw.dae" scale="0.1 0.1 0.1"/>
        <!-- The propeller meshes have a radius of 1m -->
        <!-- <box size="${2*radius_rotor} 0.01 0.005"/> -->
      </geometry>
    </visual>
    <collision>
      <geometry>
        <cylinder length="0.005" radius="0.1"/>
        <!-- [m] -->
      </geometry>
    </collision>
  </link>
  <gazebo>
    <plugin filename="librotors_gazebo_motor_model.so" name="h1_front_motor_model">
      <robotNamespace>h1</robotNamespace>
      <jointName>h1/rotor_0_joint</jointName>
      <linkName>h1/rotor_0</linkName>
      <turningDirection>cw</turningDirection>
      <timeConstantUp>0.0125</timeConstantUp>
      <timeConstantDown>0.025</timeConstantDown>
      <maxRotVelocity>838</maxRotVelocity>
      <motorConstant>8.54858e-06</motorConstant>
      <momentConstant>0.016</momentConstant>
      <commandSubTopic>gazebo/command/motor_speed</commandSubTopic>
      <motorNumber>0</motorNumber>
      <rotorDragCoefficient>8.06428e-05</rotorDragCoefficient>
      <rollingMomentCoefficient>1e-06</rollingMomentCoefficient>
      <motorSpeedPubTopic>motor_speed/0</motorSpeedPubTopic>
      <rotorVelocitySlowdownSim>10</rotorVelocitySlowdownSim>
    </plugin>
  </gazebo>
  <gazebo reference="h1/rotor_0">
    <material>Gazebo/Red</material>
  </gazebo>
  <joint name="h1/rotor_1_joint" type="continuous">
    <origin rpy="0 0 0" xyz="0 0.17 0.01"/>
    <axis xyz="0 0 1"/>
    <!-- TODO(ff): not currently set because it's not yet supported -->
    <!-- <limit effort="2000" velocity="${max_rot_velocity}" /> -->
    <parent link="h1/base_link"/>
    <child link="h1/rotor_1"/>
  </joint>
  <link name="h1/rotor_1">
    <inertial>
      <mass value="0.009"/>
      <!-- [kg] -->
      <inertia ixx="1.754999298e-06" ixy="0.0" ixz="0.0" iyy="7.506746997300002e-05" iyz="0.0" izz="7.668746932500001e-05"/>
    </inertial>
    <visual>
      <geometry>
        <mesh filename="package://rotors_description/meshes/propeller_ccw.dae" scale="0.1 0.1 0.1"/>
        <!-- The propeller meshes have a radius of 1m -->
        <!-- <box size="${2*radius_rotor} 0.01 0.005"/> -->
      </geometry>
    </visual>
    <collision>
      <geometry>
        <cylinder length="0.005" radius="0.1"/>
        <!-- [m] -->
      </geometry>
    </collision>
  </link>
  <gazebo>
    <plugin filename="librotors_gazebo_motor_model.so" name="h1_left_motor_model">
      <robotNamespace>h1</robotNamespace>
      <jointName>h1/rotor_1_joint</jointName>
      <linkName>h1/rotor_1</linkName>
      <turningDirection>ccw</turningDirection>
      <timeConstantUp>0.0125</timeConstantUp>
      <timeConstantDown>0.025</timeConstantDown>
      <maxRotVelocity>838</maxRotVelocity>
      <motorConstant>8.54858e-06</motorConstant>
      <momentConstant>0.016</momentConstant>
      <commandSubTopic>gazebo/command/motor_speed</commandSubTopic>
      <motorNumber>1</motorNumber>
      <rotorDragCoefficient>8.06428e-05</rotorDragCoefficient>
      <rollingMomentCoefficient>1e-06</rollingMomentCoefficient>
      <motorSpeedPubTopic>motor_speed/1</motorSpeedPubTopic>
      <rotorVelocitySlowdownSim>10</rotorVelocitySlowdownSim>
    </plugin>
  </gazebo>
  <gazebo reference="h1/rotor_1">
    <material>Gazebo/Blue</material>
  </gazebo>
  <joint name="h1/rotor_2_joint" type="continuous">
    <origin rpy="0 0 0" xyz="-0.17 0 0.01"/>
    <axis xyz="0 0 1"/>
    <!-- TODO(ff): not currently set because it's not yet supported -->
    <!-- <limit effort="2000" velocity="${max_rot_velocity}" /> -->
    <parent link="h1/base_link"/>
    <child link="h1/rotor_2"/>
  </joint>
  <link name="h1/rotor_2">
    <inertial>
      <mass value="0.009"/>
      <!-- [kg] -->
      <inertia ixx="1.754999298e-06" ixy="0.0" ixz="0.0" iyy="7.506746997300002e-05" iyz="0.0" izz="7.668746932500001e-05"/>
    </inertial>
    <visual>
      <geometry>
        <mesh filename="package://rotors_description/meshes/propeller_cw.dae" scale="0.1 0.1 0.1"/>
        <!-- The propeller meshes have a radius of 1m -->
        <!-- <box size="${2*radius_rotor} 0.01 0.005"/> -->
      </geometry>
    </visual>
    <collision>
      <geometry>
        <cylinder length="0.005" radius="0.1"/>
        <!-- [m] -->
      </geometry>
    </collision>
  </link>
  <gazebo>
    <plugin filename="librotors_gazebo_motor_model.so" name="h1_back_motor_model">
      <robotNamespace>h1</robotNamespace>
      <jointName>h1/rotor_2_joint</jointName>
      <linkName>h1/rotor_2</linkName>
      <turningDirection>cw</turningDirection>
      <timeConstantUp>0.0125</timeConstantUp>
      <timeConstantDown>0.025</timeConstantDown>
      <maxRotVelocity>838</maxRotVelocity>
      <motorConstant>8.54858e-06</motorConstant>
      <momentConstant>0.016</momentConstant>
      <commandSubTopic>gazebo/command/motor_speed</commandSubTopic>
      <motorNumber>2</motorNumber>
      <rotorDragCoefficient>8.06428e-05</rotorDragCoefficient>
      <rollingMomentCoefficient>1e-06</rollingMomentCoefficient>
      <motorSpeedPubTopic>motor_speed/2</motorSpeedPubTopic>
      <rotorVelocitySlowdownSim>10</rotorVelocitySlowdownSim>
    </plugin>
  </gazebo>
  <gazebo reference="h1/rotor_2">
    <material>Gazebo/Blue</material>
  </gazebo>
  <joint name="h1/rotor_3_joint" type="continuous">
    <origin rpy="0 0 0" xyz="0 -0.17 0.01"/>
    <axis xyz="0 0 1"/>
    <!-- TODO(ff): not currently set because it's not yet supported -->
    <!-- <limit effort="2000" velocity="${max_rot_velocity}" /> -->
    <parent link="h1/base_link"/>
    <child link="h1/rotor_3"/>
  </joint>
  <link name="h1/rotor_3">
    <inertial>
      <mass value="0.009"/>
      <!-- [kg] -->
      <inertia ixx="1.754999298e-06" ixy="0.0" ixz="0.0" iyy="7.506746997300002e-05" iyz="0.0" izz="7.668746932500001e-05"/>
    </inertial>
    <visual>
      <geometry>
        <mesh filename="package://rotors_description/meshes/propeller_ccw.dae" scale="0.1 0.1 0.1"/>
        <!-- The propeller meshes have a radius of 1m -->
        <!-- <box size="${2*radius_rotor} 0.01 0.005"/> -->
      </geometry>
    </visual>
    <collision>
      <geometry>
        <cylinder length="0.005" radius="0.1"/>
        <!-- [m] -->
      </geometry>
    </collision>
  </link>
  <gazebo>
    <plugin filename="librotors_gazebo_motor_model.so" name="h1_right_motor_model">
      <robotNamespace>h1</robotNamespace>
      <jointName>h1/rotor_3_joint</jointName>
      <linkName>h1/rotor_3</linkName>
      <turningDirection>ccw</turningDirection>
      <timeConstantUp>0.0125</timeConstantUp>
      <timeConstantDown>0.025</timeConstantDown>
      <maxRotVelocity>838</maxRotVelocity>
      <motorConstant>8.54858e-06</motorConstant>
      <momentConstant>0.016</momentConstant>
      <commandSubTopic>gazebo/command/motor_speed</commandSubTopic>
      <motorNumber>3</motorNumber>
      <rotorDragCoefficient>8.06428e-05</rotorDragCoefficient>
      <rollingMomentCoefficient>1e-06</rollingMomentCoefficient>
      <motorSpeedPubTopic>motor_speed/3</motorSpeedPubTopic>
      <rotorVelocitySlowdownSim>10</rotorVelocitySlowdownSim>
    </plugin>
  </gazebo>
  <gazebo reference="h1/rotor_3">
    <material>Gazebo/Blue</material>
  </gazebo>
</robot>

